Workbook

Sheet Read Me
A1: This spreadsheet was created by Aaron Brown on March 17, 2019, this version March 18, 2019 with updated frequency estimates from ESPN pool data
A3: It is an experimental system for using factor investing principles to make NCAA bracket pool selections
A5: Use at your own risk, I make no representations about the quality of the system or the accuracy of the spreadsheet
A7: Read the paper available at https://www.eraider.com/nfl-picks for important qualifications
A9: Everything you need is in the Bracket tab, the other tabs are for data input or calculation
A11: All cells in the workbook are protected, but without password, except the round point values at the top left of the Bracket tab
A13: Protection is only to stop accidental changes, feel free to remove it and modify as you like
A15: You can set your own round point values (the spreadsheet does not accommodate seed-based or other more complex scoring systems)
A17: You can change anything else you like, including measures of quality, size and momentum; and slot probabilities and frequencies
A19: The system gives star ratings to every slot pick, but it does not account for how many upsets you should pick
A21: You can work from round 1 forward, or the champion backward, or any other way you like
A23: Except perhaps in the largest pools, such as national competitions with millions of entries, picking the top star rating at every opportunity will result in far too many and too unlikely upset picksl Keep an eye on the estimated win probability. Don't use it to make picks, because it assumes that the probability and frequency tables are exactly correct. The entire point of the spreadsheet is to take advantage of deviations from those values. But the estimated win probability is useful to tell you if you have about the correct number of upset picks. If your win probability is below one over the effective pool size, you have either too many upset picks, or too unlikely upset picks. If it's too high, don't trust it for the reason given in the next paragraph. Typical good bracket selections will have expected win probabilities around two divided by the effective pool size to three divided by the expected pool size.
A25: The system does not account for game theory considerations, such that other people in your pool may use the same or similar methodologies so your picks could be correlated. This is particularly important when interpreting the estimated win probability. For example, picking all favorites may look good, and it could be good if everyone else in the pool picked according to the frequency assumptions. But some people will pick nearly all favorites, while others will pick many longshots. So it's important to make your picks different from other people's, even if that results in a somewhat lower estimated win probability.

Sheet Sheet1

Sheet Bracket
A1: Input parameters | D1: Total | E1: R64 | F1: R32 | G1: S16 | H1: E8 | I1: F4 | J1: C6 | L1: Your estimated chance of winning the pool | O1: =SUM(P7:AB7)
A2: Points per round | D2: =32*E2+16*F2+8*G2+4*H2+2*I2+J2 | E2: 2 | F2: 3 | G2: 5 | H2: 8 | I2: 13 | J2: 21
A3: Effective pool size | D3: 100
A4: Score distributions | D4: Total | E4: R64 | F4: R32 | G4: S16 | H4: E8 | I4: F4 | J4: C6 | L4: Probability | O4: =MIN(1,2*P4) | P4: =MIN(1,2*Q4) | Q4: =MIN(1,2*R4) | R4: =MIN(1,2*S4) | S4: =MIN(1,2*T4) | T4: =MIN(1,2*U4) | U4: =MIN(1,2*V4) | V4: =1/D3 | W4: =V4/2 | X4: =W4/2 | Y4: =X4/2 | Z4: =Y4/2 | AA4: =Z4/2 | AB4: 0
A5: Expected points | C5: You | D5: =SUM(E5:J5) | E5: =E2*SUMPRODUCT(E14:E77,'Brackets - prob'!B2:B65) | F5: =F2*SUMPRODUCT(F14:F77,'Brackets - prob'!C2:C65) | G5: =G2*SUMPRODUCT(G14:G77,'Brackets - prob'!D2:D65) | H5: =H2*SUMPRODUCT(H14:H77,'Brackets - prob'!E2:E65) | I5: =I2*SUMPRODUCT(I14:I77,'Brackets - prob'!F2:F65) | J5: =J2*SUMPRODUCT(J14:J77,'Brackets - prob'!G2:G65) | L5: Your score deviation | O5: =-D2 | P5: =$D10+NORMSINV(1-P4)*$E10 | Q5: =$D10+NORMSINV(1-Q4)*$E10 | R5: =$D10+NORMSINV(1-R4)*$E10 | S5: =$D10+NORMSINV(1-S4)*$E10 | T5: =$D10+NORMSINV(1-T4)*$E10 | U5: =$D10+NORMSINV(1-U4)*$E10 | V5: =$D10+NORMSINV(1-V4)*$E10 | W5: =$D10+NORMSINV(1-W4)*$E10 | ... AA5: =$D10+NORMSINV(1-AA4)*$E10 | AB5: =D2
C6: Field | D6: =SUM(E6:J6) | E6: =E2*SUMPRODUCT('Brackets - prob'!B2:B65,'Brackets - freq'!B2:B65) | F6: =F2*SUMPRODUCT('Brackets - prob'!C2:C65,'Brackets - freq'!C2:C65) | G6: =G2*SUMPRODUCT('Brackets - prob'!D2:D65,'Brackets - freq'!D2:D65) | H6: =H2*SUMPRODUCT('Brackets - prob'!E2:E65,'Brackets - freq'!E2:E65) | I6: =I2*SUMPRODUCT('Brackets - prob'!F2:F65,'Brackets - freq'!F2:F65) | J6: =J2*SUMPRODUCT('Brackets - prob'!G2:G65,'Brackets - freq'!G2:G65) | L6: Pool win probability | O6: 0 | P6: =NORMDIST(P5,$D11,$E11,TRUE)^($D3-1) | Q6: =NORMDIST(Q5,$D11,$E11,TRUE)^($D3-1) | R6: =NORMDIST(R5,$D11,$E11,TRUE)^($D3-1) | S6: =NORMDIST(S5,$D11,$E11,TRUE)^($D3-1) | T6: =NORMDIST(T5,$D11,$E11,TRUE)^($D3-1) | U6: =NORMDIST(U5,$D11,$E11,TRUE)^($D3-1) | V6: =NORMDIST(V5,$D11,$E11,TRUE)^($D3-1) | W6: =NORMDIST(W5,$D11,$E11,TRUE)^($D3-1) | ... AA6: =NORMDIST(AA5,$D11,$E11,TRUE)^($D3-1) | AB6: 1
A7: Deviation variance | C7: You | D7: =SUM(E7:J7) | E7: =E2^2*SUMPRODUCT(E14:E77,'Slot calculations'!AF3:AF66) | F7: =F2^2*SUMPRODUCT(F14:F77,'Slot calculations'!AG3:AG66) | G7: =G2^2*SUMPRODUCT(G14:G77,'Slot calculations'!AH3:AH66) | H7: =H2^2*SUMPRODUCT(H14:H77,'Slot calculations'!AI3:AI66) | I7: =I2^2*SUMPRODUCT(I14:I77,'Slot calculations'!AJ3:AJ66) | J7: =J2^2*SUMPRODUCT(J14:J77,'Slot calculations'!AK3:AK66) | L7: Contribution to total | P7: =(O4-P4)*(O6+P6)/2 | Q7: =(P4-Q4)*(P6+Q6)/2 | R7: =(Q4-R4)*(Q6+R6)/2 | S7: =(R4-S4)*(R6+S6)/2 | T7: =(S4-T4)*(S6+T6)/2 | U7: =(T4-U4)*(T6+U6)/2 | V7: =(U4-V4)*(U6+V6)/2 | W7: =(V4-W4)*(V6+W6)/2 | ... AB7: =(AA4-AB4)*(AA6+AB6)/2
C8: Field | D8: =SUM(E8:J8) | E8: =E2^2*SUMPRODUCT('Brackets - freq'!B2:B65,'Slot calculations'!AF3:AF66) | F8: =F2^2*SUMPRODUCT('Brackets - freq'!C2:C65,'Slot calculations'!AG3:AG66) | G8: =G2^2*SUMPRODUCT('Brackets - freq'!D2:D65,'Slot calculations'!AH3:AH66) | H8: =H2^2*SUMPRODUCT('Brackets - freq'!E2:E65,'Slot calculations'!AI3:AI66) | I8: =I2^2*SUMPRODUCT('Brackets - freq'!F2:F65,'Slot calculations'!AJ3:AJ66) | J8: =J2^2*SUMPRODUCT('Brackets - freq'!G2:G65,'Slot calculations'!AK3:AK66)
D9: Mean | E9: Std dev
A10: Deviation parameters | C10: You | D10: =D5-D6 | E10: =SQRT(D7)
C11: Field | D11: 0 | E11: =SQRT(D8)
A12: Seed | B12: Team | E12: Picks | K12: Star ratings | Q12: Raw Values | T12: Median | V12: Indicator | Y12: Value | AE12: BAB
E13: R64 | F13: R32 | G13: S16 | H13: E8 | I13: F4 | J13: C6 | K13: R64 | L13: R32 | M13: S16 | N13: E8 | O13: F4 | P13: C6 | Q13: Quality | R13: Size | S13: Mom | T13: Quality | U13: Size | V13: Quality | W13: Size | X13: Mom | Y13: R64 | Z13: R32 | AA13: S16 | AB13: E8 | AC13: F4 | AD13: C6 | AE13: R64 | AF13: R32 | AG13: S16 | AH13: E8 | AI13: F4 | AJ13: C6
A14: 1 | B14: Duke | E14: 1 | F14: 1 | G14: 1 | H14: 1 | I14: 1 | J14: 1 | K14: =REPT(CHAR(152),SUM($V14:$X14)+Y14+AE14) | L14: =REPT(CHAR(152),SUM($V14:$X14)+Z14+AF14) | M14: =REPT(CHAR(152),SUM($V14:$X14)+AA14+AG14) | N14: =REPT(CHAR(152),SUM($V14:$X14)+AB14+AH14) | O14: =REPT(CHAR(152),SUM($V14:$X14)+AC14+AI14) | P14: =REPT(CHAR(152),SUM($V14:$X14)+AD14+AJ14) | Q14: =VLOOKUP(B14,Quality!A$2:B$252,2,FALSE) | R14: =VLOOKUP(B14,Size!A$2:B$299,2,FALSE) | S14: =VLOOKUP(B14,Mom!A$2:B$68,2,FALSE) | T14: {=MEDIAN(IF($A$14:$A$77=$A14,Q$14:Q$77))} | U14: {=MEDIAN(IF($A$14:$A$77=$A14,R$14:R$77))} | V14: =IF(Q14>T14,1,0) | W14: =IF(R14>U14,1,0) | X14: =IF(OR(AND(A14<9,S14>3),AND(A14>8,S14<4)),1,0) | Y14: ='Slot calculations'!BD3 | Z14: ='Slot calculations'!BE3 | AA14: ='Slot calculations'!BF3 | AB14: ='Slot calculations'!BG3 | AC14: ='Slot calculations'!BH3 | AD14: ='Slot calculations'!BI3 | AE14: ='Slot calculations'!BJ3 | AF14: ='Slot calculations'!BK3 | ... AJ14: ='Slot calculations'!BO3
A15: 16 | B15: NDS/NCC | E15: 0 | F15: 0 | G15: 0 | H15: 0 | I15: 0 | J15: 0 | K15: =REPT(CHAR(152),SUM($V15:$X15)+Y15+AE15) | L15: =REPT(CHAR(152),SUM($V15:$X15)+Z15+AF15) | M15: =REPT(CHAR(152),SUM($V15:$X15)+AA15+AG15) | N15: =REPT(CHAR(152),SUM($V15:$X15)+AB15+AH15) | O15: =REPT(CHAR(152),SUM($V15:$X15)+AC15+AI15) | P15: =REPT(CHAR(152),SUM($V15:$X15)+AD15+AJ15) | Q15: =(Q78+Q79)/2 | R15: =(R78+R79)/2 | S15: =(S78+S79)/2 | T15: {=MEDIAN(IF($A$14:$A$77=$A15,Q$14:Q$77))} | U15: {=MEDIAN(IF($A$14:$A$77=$A15,R$14:R$77))} | V15: =IF(Q15>T15,1,0) | W15: =IF(R15>U15,1,0) | X15: =IF(OR(AND(A15<9,S15>3),AND(A15>8,S15<4)),1,0) | Y15: ='Slot calculations'!BD4 | Z15: ='Slot calculations'!BE4 | AA15: ='Slot calculations'!BF4 | AB15: ='Slot calculations'!BG4 | AC15: ='Slot calculations'!BH4 | AD15: ='Slot calculations'!BI4 | AE15: ='Slot calculations'!BJ4 | AF15: ='Slot calculations'!BK4 | ... AJ15: ='Slot calculations'!BO4
A16: 8 | B16: VCU | E16: 1 | F16: 0 | G16: 0 | H16: 0 | I16: 0 | J16: 0 | K16: =REPT(CHAR(152),SUM($V16:$X16)+Y16+AE16) | L16: =REPT(CHAR(152),SUM($V16:$X16)+Z16+AF16) | M16: =REPT(CHAR(152),SUM($V16:$X16)+AA16+AG16) | N16: =REPT(CHAR(152),SUM($V16:$X16)+AB16+AH16) | O16: =REPT(CHAR(152),SUM($V16:$X16)+AC16+AI16) | P16: =REPT(CHAR(152),SUM($V16:$X16)+AD16+AJ16) | Q16: =VLOOKUP(B16,Quality!A$2:B$252,2,FALSE) | R16: =VLOOKUP(B16,Size!A$2:B$299,2,FALSE) | S16: =VLOOKUP(B16,Mom!A$2:B$68,2,FALSE) | T16: {=MEDIAN(IF($A$14:$A$77=$A16,Q$14:Q$77))} | U16: {=MEDIAN(IF($A$14:$A$77=$A16,R$14:R$77))} | V16: =IF(Q16>T16,1,0) | W16: =IF(R16>U16,1,0) | X16: =IF(OR(AND(A16<9,S16>3),AND(A16>8,S16<4)),1,0) | Y16: ='Slot calculations'!BD5 | Z16: ='Slot calculations'!BE5 | AA16: ='Slot calculations'!BF5 | AB16: ='Slot calculations'!BG5 | AC16: ='Slot calculations'!BH5 | AD16: ='Slot calculations'!BI5 | AE16: ='Slot calculations'!BJ5 | AF16: ='Slot calculations'!BK5 | ... AJ16: ='Slot calculations'!BO5
A17: 9 | B17: UCF | E17: 0 | F17: 0 | G17: 0 | H17: 0 | I17: 0 | J17: 0 | K17: =REPT(CHAR(152),SUM($V17:$X17)+Y17+AE17) | L17: =REPT(CHAR(152),SUM($V17:$X17)+Z17+AF17) | M17: =REPT(CHAR(152),SUM($V17:$X17)+AA17+AG17) | N17: =REPT(CHAR(152),SUM($V17:$X17)+AB17+AH17) | O17: =REPT(CHAR(152),SUM($V17:$X17)+AC17+AI17) | P17: =REPT(CHAR(152),SUM($V17:$X17)+AD17+AJ17) | Q17: =VLOOKUP(B17,Quality!A$2:B$252,2,FALSE) | R17: =VLOOKUP(B17,Size!A$2:B$299,2,FALSE) | S17: =VLOOKUP(B17,Mom!A$2:B$68,2,FALSE) | T17: {=MEDIAN(IF($A$14:$A$77=$A17,Q$14:Q$77))} | U17: {=MEDIAN(IF($A$14:$A$77=$A17,R$14:R$77))} | V17: =IF(Q17>T17,1,0) | W17: =IF(R17>U17,1,0) | X17: =IF(OR(AND(A17<9,S17>3),AND(A17>8,S17<4)),1,0) | Y17: ='Slot calculations'!BD6 | Z17: ='Slot calculations'!BE6 | AA17: ='Slot calculations'!BF6 | AB17: ='Slot calculations'!BG6 | AC17: ='Slot calculations'!BH6 | AD17: ='Slot calculations'!BI6 | AE17: ='Slot calculations'!BJ6 | AF17: ='Slot calculations'!BK6 | ... AJ17: ='Slot calculations'!BO6
A18: 5 | B18: Mississippi State | E18: 1 | F18: 1 | G18: 0 | H18: 0 | I18: 0 | J18: 0 | K18: =REPT(CHAR(152),SUM($V18:$X18)+Y18+AE18) | L18: =REPT(CHAR(152),SUM($V18:$X18)+Z18+AF18) | M18: =REPT(CHAR(152),SUM($V18:$X18)+AA18+AG18) | N18: =REPT(CHAR(152),SUM($V18:$X18)+AB18+AH18) | O18: =REPT(CHAR(152),SUM($V18:$X18)+AC18+AI18) | P18: =REPT(CHAR(152),SUM($V18:$X18)+AD18+AJ18) | Q18: =VLOOKUP(B18,Quality!A$2:B$252,2,FALSE) | R18: =VLOOKUP(B18,Size!A$2:B$299,2,FALSE) | S18: =VLOOKUP(B18,Mom!A$2:B$68,2,FALSE) | T18: {=MEDIAN(IF($A$14:$A$77=$A18,Q$14:Q$77))} | U18: {=MEDIAN(IF($A$14:$A$77=$A18,R$14:R$77))} | V18: =IF(Q18>T18,1,0) | W18: =IF(R18>U18,1,0) | X18: =IF(OR(AND(A18<9,S18>3),AND(A18>8,S18<4)),1,0) | Y18: ='Slot calculations'!BD7 | Z18: ='Slot calculations'!BE7 | AA18: ='Slot calculations'!BF7 | AB18: ='Slot calculations'!BG7 | AC18: ='Slot calculations'!BH7 | AD18: ='Slot calculations'!BI7 | AE18: ='Slot calculations'!BJ7 | AF18: ='Slot calculations'!BK7 | ... AJ18: ='Slot calculations'!BO7
A19: 12 | B19: Liberty | E19: 0 | F19: 0 | G19: 0 | H19: 0 | I19: 0 | J19: 0 | K19: =REPT(CHAR(152),SUM($V19:$X19)+Y19+AE19) | L19: =REPT(CHAR(152),SUM($V19:$X19)+Z19+AF19) | M19: =REPT(CHAR(152),SUM($V19:$X19)+AA19+AG19) | N19: =REPT(CHAR(152),SUM($V19:$X19)+AB19+AH19) | O19: =REPT(CHAR(152),SUM($V19:$X19)+AC19+AI19) | P19: =REPT(CHAR(152),SUM($V19:$X19)+AD19+AJ19) | Q19: =VLOOKUP(B19,Quality!A$2:B$252,2,FALSE) | R19: =VLOOKUP(B19,Size!A$2:B$299,2,FALSE) | S19: =VLOOKUP(B19,Mom!A$2:B$68,2,FALSE) | T19: {=MEDIAN(IF($A$14:$A$77=$A19,Q$14:Q$77))} | U19: {=MEDIAN(IF($A$14:$A$77=$A19,R$14:R$77))} | V19: =IF(Q19>T19,1,0) | W19: =IF(R19>U19,1,0) | X19: =IF(OR(AND(A19<9,S19>3),AND(A19>8,S19<4)),1,0) | Y19: ='Slot calculations'!BD8 | Z19: ='Slot calculations'!BE8 | AA19: ='Slot calculations'!BF8 | AB19: ='Slot calculations'!BG8 | AC19: ='Slot calculations'!BH8 | AD19: ='Slot calculations'!BI8 | AE19: ='Slot calculations'!BJ8 | AF19: ='Slot calculations'!BK8 | ... AJ19: ='Slot calculations'!BO8
A20: 4 | B20: Virginia Tech | E20: 1 | F20: 0 | G20: 0 | H20: 0 | I20: 0 | J20: 0 | K20: =REPT(CHAR(152),SUM($V20:$X20)+Y20+AE20) | L20: =REPT(CHAR(152),SUM($V20:$X20)+Z20+AF20) | M20: =REPT(CHAR(152),SUM($V20:$X20)+AA20+AG20) | N20: =REPT(CHAR(152),SUM($V20:$X20)+AB20+AH20) | O20: =REPT(CHAR(152),SUM($V20:$X20)+AC20+AI20) | P20: =REPT(CHAR(152),SUM($V20:$X20)+AD20+AJ20) | Q20: =VLOOKUP(B20,Quality!A$2:B$252,2,FALSE) | R20: =VLOOKUP(B20,Size!A$2:B$299,2,FALSE) | S20: =VLOOKUP(B20,Mom!A$2:B$68,2,FALSE) | T20: {=MEDIAN(IF($A$14:$A$77=$A20,Q$14:Q$77))} | U20: {=MEDIAN(IF($A$14:$A$77=$A20,R$14:R$77))} | V20: =IF(Q20>T20,1,0) | W20: =IF(R20>U20,1,0) | X20: =IF(OR(AND(A20<9,S20>3),AND(A20>8,S20<4)),1,0) | Y20: ='Slot calculations'!BD9 | Z20: ='Slot calculations'!BE9 | AA20: ='Slot calculations'!BF9 | AB20: ='Slot calculations'!BG9 | AC20: ='Slot calculations'!BH9 | AD20: ='Slot calculations'!BI9 | AE20: ='Slot calculations'!BJ9 | AF20: ='Slot calculations'!BK9 | ... AJ20: ='Slot calculations'!BO9
A21: 13 | B21: Saint Louis | E21: 0 | F21: 0 | G21: 0 | H21: 0 | I21: 0 | J21: 0 | K21: =REPT(CHAR(152),SUM($V21:$X21)+Y21+AE21) | L21: =REPT(CHAR(152),SUM($V21:$X21)+Z21+AF21) | M21: =REPT(CHAR(152),SUM($V21:$X21)+AA21+AG21) | N21: =REPT(CHAR(152),SUM($V21:$X21)+AB21+AH21) | O21: =REPT(CHAR(152),SUM($V21:$X21)+AC21+AI21) | P21: =REPT(CHAR(152),SUM($V21:$X21)+AD21+AJ21) | Q21: =VLOOKUP(B21,Quality!A$2:B$252,2,FALSE) | R21: =VLOOKUP(B21,Size!A$2:B$299,2,FALSE) | S21: =VLOOKUP(B21,Mom!A$2:B$68,2,FALSE) | T21: {=MEDIAN(IF($A$14:$A$77=$A21,Q$14:Q$77))} | U21: {=MEDIAN(IF($A$14:$A$77=$A21,R$14:R$77))} | V21: =IF(Q21>T21,1,0) | W21: =IF(R21>U21,1,0) | X21: =IF(OR(AND(A21<9,S21>3),AND(A21>8,S21<4)),1,0) | Y21: ='Slot calculations'!BD10 | Z21: ='Slot calculations'!BE10 | AA21: ='Slot calculations'!BF10 | AB21: ='Slot calculations'!BG10 | AC21: ='Slot calculations'!BH10 | AD21: ='Slot calculations'!BI10 | AE21: ='Slot calculations'!BJ10 | AF21: ='Slot calculations'!BK10 | ... AJ21: ='Slot calculations'!BO10
A22: 6 | B22: Maryland | E22: 1 | F22: 1 | G22: 1 | H22: 0 | I22: 0 | J22: 0 | K22: =REPT(CHAR(152),SUM($V22:$X22)+Y22+AE22) | L22: =REPT(CHAR(152),SUM($V22:$X22)+Z22+AF22) | M22: =REPT(CHAR(152),SUM($V22:$X22)+AA22+AG22) | N22: =REPT(CHAR(152),SUM($V22:$X22)+AB22+AH22) | O22: =REPT(CHAR(152),SUM($V22:$X22)+AC22+AI22) | P22: =REPT(CHAR(152),SUM($V22:$X22)+AD22+AJ22) | Q22: =VLOOKUP(B22,Quality!A$2:B$252,2,FALSE) | R22: =VLOOKUP(B22,Size!A$2:B$299,2,FALSE) | S22: =VLOOKUP(B22,Mom!A$2:B$68,2,FALSE) | T22: {=MEDIAN(IF($A$14:$A$77=$A22,Q$14:Q$77))} | U22: {=MEDIAN(IF($A$14:$A$77=$A22,R$14:R$77))} | V22: =IF(Q22>T22,1,0) | W22: =IF(R22>U22,1,0) | X22: =IF(OR(AND(A22<9,S22>3),AND(A22>8,S22<4)),1,0) | Y22: ='Slot calculations'!BD11 | Z22: ='Slot calculations'!BE11 | AA22: ='Slot calculations'!BF11 | AB22: ='Slot calculations'!BG11 | AC22: ='Slot calculations'!BH11 | AD22: ='Slot calculations'!BI11 | AE22: ='Slot calculations'!BJ11 | AF22: ='Slot calculations'!BK11 | ... AJ22: ='Slot calculations'!BO11
A23: 11 | B23: Bel/Tem | E23: 0 | F23: 0 | G23: 0 | H23: 0 | I23: 0 | J23: 0 | K23: =REPT(CHAR(152),SUM($V23:$X23)+Y23+AE23) | L23: =REPT(CHAR(152),SUM($V23:$X23)+Z23+AF23) | M23: =REPT(CHAR(152),SUM($V23:$X23)+AA23+AG23) | N23: =REPT(CHAR(152),SUM($V23:$X23)+AB23+AH23) | O23: =REPT(CHAR(152),SUM($V23:$X23)+AC23+AI23) | P23: =REPT(CHAR(152),SUM($V23:$X23)+AD23+AJ23) | Q23: =(Q80+Q81)/2 | R23: =(R80+R81)/2 | S23: =(S80+S81)/2 | T23: {=MEDIAN(IF($A$14:$A$77=$A23,Q$14:Q$77))} | U23: {=MEDIAN(IF($A$14:$A$77=$A23,R$14:R$77))} | V23: =IF(Q23>T23,1,0) | W23: =IF(R23>U23,1,0) | X23: =IF(OR(AND(A23<9,S23>3),AND(A23>8,S23<4)),1,0) | Y23: ='Slot calculations'!BD12 | Z23: ='Slot calculations'!BE12 | AA23: ='Slot calculations'!BF12 | AB23: ='Slot calculations'!BG12 | AC23: ='Slot calculations'!BH12 | AD23: ='Slot calculations'!BI12 | AE23: ='Slot calculations'!BJ12 | AF23: ='Slot calculations'!BK12 | ... AJ23: ='Slot calculations'!BO12
A24: 3 | B24: LSU | E24: 1 | F24: 0 | G24: 0 | H24: 0 | I24: 0 | J24: 0 | K24: =REPT(CHAR(152),SUM($V24:$X24)+Y24+AE24) | L24: =REPT(CHAR(152),SUM($V24:$X24)+Z24+AF24) | M24: =REPT(CHAR(152),SUM($V24:$X24)+AA24+AG24) | N24: =REPT(CHAR(152),SUM($V24:$X24)+AB24+AH24) | O24: =REPT(CHAR(152),SUM($V24:$X24)+AC24+AI24) | P24: =REPT(CHAR(152),SUM($V24:$X24)+AD24+AJ24) | Q24: =VLOOKUP(B24,Quality!A$2:B$252,2,FALSE) | R24: =VLOOKUP(B24,Size!A$2:B$299,2,FALSE) | S24: =VLOOKUP(B24,Mom!A$2:B$68,2,FALSE) | T24: {=MEDIAN(IF($A$14:$A$77=$A24,Q$14:Q$77))} | U24: {=MEDIAN(IF($A$14:$A$77=$A24,R$14:R$77))} | V24: =IF(Q24>T24,1,0) | W24: =IF(R24>U24,1,0) | X24: =IF(OR(AND(A24<9,S24>3),AND(A24>8,S24<4)),1,0) | Y24: ='Slot calculations'!BD13 | Z24: ='Slot calculations'!BE13 | AA24: ='Slot calculations'!BF13 | AB24: ='Slot calculations'!BG13 | AC24: ='Slot calculations'!BH13 | AD24: ='Slot calculations'!BI13 | AE24: ='Slot calculations'!BJ13 | AF24: ='Slot calculations'!BK13 | ... AJ24: ='Slot calculations'!BO13
A25: 14 | B25: Yale | E25: 0 | F25: 0 | G25: 0 | H25: 0 | I25: 0 | J25: 0 | K25: =REPT(CHAR(152),SUM($V25:$X25)+Y25+AE25) | L25: =REPT(CHAR(152),SUM($V25:$X25)+Z25+AF25) | M25: =REPT(CHAR(152),SUM($V25:$X25)+AA25+AG25) | N25: =REPT(CHAR(152),SUM($V25:$X25)+AB25+AH25) | O25: =REPT(CHAR(152),SUM($V25:$X25)+AC25+AI25) | P25: =REPT(CHAR(152),SUM($V25:$X25)+AD25+AJ25) | Q25: =VLOOKUP(B25,Quality!A$2:B$252,2,FALSE) | R25: =VLOOKUP(B25,Size!A$2:B$299,2,FALSE) | S25: =VLOOKUP(B25,Mom!A$2:B$68,2,FALSE) | T25: {=MEDIAN(IF($A$14:$A$77=$A25,Q$14:Q$77))} | U25: {=MEDIAN(IF($A$14:$A$77=$A25,R$14:R$77))} | V25: =IF(Q25>T25,1,0) | W25: =IF(R25>U25,1,0) | X25: =IF(OR(AND(A25<9,S25>3),AND(A25>8,S25<4)),1,0) | Y25: ='Slot calculations'!BD14 | Z25: ='Slot calculations'!BE14 | AA25: ='Slot calculations'!BF14 | AB25: ='Slot calculations'!BG14 | AC25: ='Slot calculations'!BH14 | AD25: ='Slot calculations'!BI14 | AE25: ='Slot calculations'!BJ14 | AF25: ='Slot calculations'!BK14 | ... AJ25: ='Slot calculations'!BO14
A26: 7 | B26: Louisville | E26: 1 | F26: 1 | G26: 0 | H26: 0 | I26: 0 | J26: 0 | K26: =REPT(CHAR(152),SUM($V26:$X26)+Y26+AE26) | L26: =REPT(CHAR(152),SUM($V26:$X26)+Z26+AF26) | M26: =REPT(CHAR(152),SUM($V26:$X26)+AA26+AG26) | N26: =REPT(CHAR(152),SUM($V26:$X26)+AB26+AH26) | O26: =REPT(CHAR(152),SUM($V26:$X26)+AC26+AI26) | P26: =REPT(CHAR(152),SUM($V26:$X26)+AD26+AJ26) | Q26: =VLOOKUP(B26,Quality!A$2:B$252,2,FALSE) | R26: =VLOOKUP(B26,Size!A$2:B$299,2,FALSE) | S26: =VLOOKUP(B26,Mom!A$2:B$68,2,FALSE) | T26: {=MEDIAN(IF($A$14:$A$77=$A26,Q$14:Q$77))} | U26: {=MEDIAN(IF($A$14:$A$77=$A26,R$14:R$77))} | V26: =IF(Q26>T26,1,0) | W26: =IF(R26>U26,1,0) | X26: =IF(OR(AND(A26<9,S26>3),AND(A26>8,S26<4)),1,0) | Y26: ='Slot calculations'!BD15 | Z26: ='Slot calculations'!BE15 | AA26: ='Slot calculations'!BF15 | AB26: ='Slot calculations'!BG15 | AC26: ='Slot calculations'!BH15 | AD26: ='Slot calculations'!BI15 | AE26: ='Slot calculations'!BJ15 | AF26: ='Slot calculations'!BK15 | ... AJ26: ='Slot calculations'!BO15
A27: 10 | B27: Minnesota | E27: 0 | F27: 0 | G27: 0 | H27: 0 | I27: 0 | J27: 0 | K27: =REPT(CHAR(152),SUM($V27:$X27)+Y27+AE27) | L27: =REPT(CHAR(152),SUM($V27:$X27)+Z27+AF27) | M27: =REPT(CHAR(152),SUM($V27:$X27)+AA27+AG27) | N27: =REPT(CHAR(152),SUM($V27:$X27)+AB27+AH27) | O27: =REPT(CHAR(152),SUM($V27:$X27)+AC27+AI27) | P27: =REPT(CHAR(152),SUM($V27:$X27)+AD27+AJ27) | Q27: =VLOOKUP(B27,Quality!A$2:B$252,2,FALSE) | R27: =VLOOKUP(B27,Size!A$2:B$299,2,FALSE) | S27: =VLOOKUP(B27,Mom!A$2:B$68,2,FALSE) | T27: {=MEDIAN(IF($A$14:$A$77=$A27,Q$14:Q$77))} | U27: {=MEDIAN(IF($A$14:$A$77=$A27,R$14:R$77))} | V27: =IF(Q27>T27,1,0) | W27: =IF(R27>U27,1,0) | X27: =IF(OR(AND(A27<9,S27>3),AND(A27>8,S27<4)),1,0) | Y27: ='Slot calculations'!BD16 | Z27: ='Slot calculations'!BE16 | AA27: ='Slot calculations'!BF16 | AB27: ='Slot calculations'!BG16 | AC27: ='Slot calculations'!BH16 | AD27: ='Slot calculations'!BI16 | AE27: ='Slot calculations'!BJ16 | AF27: ='Slot calculations'!BK16 | ... AJ27: ='Slot calculations'!BO16
A28: 2 | B28: Michigan State | E28: 1 | F28: 0 | G28: 0 | H28: 0 | I28: 0 | J28: 0 | K28: =REPT(CHAR(152),SUM($V28:$X28)+Y28+AE28) | L28: =REPT(CHAR(152),SUM($V28:$X28)+Z28+AF28) | M28: =REPT(CHAR(152),SUM($V28:$X28)+AA28+AG28) | N28: =REPT(CHAR(152),SUM($V28:$X28)+AB28+AH28) | O28: =REPT(CHAR(152),SUM($V28:$X28)+AC28+AI28) | P28: =REPT(CHAR(152),SUM($V28:$X28)+AD28+AJ28) | Q28: =VLOOKUP(B28,Quality!A$2:B$252,2,FALSE) | R28: =VLOOKUP(B28,Size!A$2:B$299,2,FALSE) | S28: =VLOOKUP(B28,Mom!A$2:B$68,2,FALSE) | T28: {=MEDIAN(IF($A$14:$A$77=$A28,Q$14:Q$77))} | U28: {=MEDIAN(IF($A$14:$A$77=$A28,R$14:R$77))} | V28: =IF(Q28>T28,1,0) | W28: =IF(R28>U28,1,0) | X28: =IF(OR(AND(A28<9,S28>3),AND(A28>8,S28<4)),1,0) | Y28: ='Slot calculations'!BD17 | Z28: ='Slot calculations'!BE17 | AA28: ='Slot calculations'!BF17 | AB28: ='Slot calculations'!BG17 | AC28: ='Slot calculations'!BH17 | AD28: ='Slot calculations'!BI17 | AE28: ='Slot calculations'!BJ17 | AF28: ='Slot calculations'!BK17 | ... AJ28: ='Slot calculations'!BO17
A29: 15 | B29: Bradley | E29: 0 | F29: 0 | G29: 0 | H29: 0 | I29: 0 | J29: 0 | K29: =REPT(CHAR(152),SUM($V29:$X29)+Y29+AE29) | L29: =REPT(CHAR(152),SUM($V29:$X29)+Z29+AF29) | M29: =REPT(CHAR(152),SUM($V29:$X29)+AA29+AG29) | N29: =REPT(CHAR(152),SUM($V29:$X29)+AB29+AH29) | O29: =REPT(CHAR(152),SUM($V29:$X29)+AC29+AI29) | P29: =REPT(CHAR(152),SUM($V29:$X29)+AD29+AJ29) | Q29: =VLOOKUP(B29,Quality!A$2:B$252,2,FALSE) | R29: =VLOOKUP(B29,Size!A$2:B$299,2,FALSE) | S29: =VLOOKUP(B29,Mom!A$2:B$68,2,FALSE) | T29: {=MEDIAN(IF($A$14:$A$77=$A29,Q$14:Q$77))} | U29: {=MEDIAN(IF($A$14:$A$77=$A29,R$14:R$77))} | V29: =IF(Q29>T29,1,0) | W29: =IF(R29>U29,1,0) | X29: =IF(OR(AND(A29<9,S29>3),AND(A29>8,S29<4)),1,0) | Y29: ='Slot calculations'!BD18 | Z29: ='Slot calculations'!BE18 | AA29: ='Slot calculations'!BF18 | AB29: ='Slot calculations'!BG18 | AC29: ='Slot calculations'!BH18 | AD29: ='Slot calculations'!BI18 | AE29: ='Slot calculations'!BJ18 | AF29: ='Slot calculations'!BK18 | ... AJ29: ='Slot calculations'!BO18
A30: 1 | B30: Gonzaga | E30: 1 | F30: 1 | G30: 1 | H30: 1 | I30: 0 | J30: 0 | K30: =REPT(CHAR(152),SUM($V30:$X30)+Y30+AE30) | L30: =REPT(CHAR(152),SUM($V30:$X30)+Z30+AF30) | M30: =REPT(CHAR(152),SUM($V30:$X30)+AA30+AG30) | N30: =REPT(CHAR(152),SUM($V30:$X30)+AB30+AH30) | O30: =REPT(CHAR(152),SUM($V30:$X30)+AC30+AI30) | P30: =REPT(CHAR(152),SUM($V30:$X30)+AD30+AJ30) | Q30: =VLOOKUP(B30,Quality!A$2:B$252,2,FALSE) | R30: =VLOOKUP(B30,Size!A$2:B$299,2,FALSE) | S30: =VLOOKUP(B30,Mom!A$2:B$68,2,FALSE) | T30: {=MEDIAN(IF($A$14:$A$77=$A30,Q$14:Q$77))} | U30: {=MEDIAN(IF($A$14:$A$77=$A30,R$14:R$77))} | V30: =IF(Q30>T30,1,0) | W30: =IF(R30>U30,1,0) | X30: =IF(OR(AND(A30<9,S30>3),AND(A30>8,S30<4)),1,0) | Y30: ='Slot calculations'!BD19 | Z30: ='Slot calculations'!BE19 | AA30: ='Slot calculations'!BF19 | AB30: ='Slot calculations'!BG19 | AC30: ='Slot calculations'!BH19 | AD30: ='Slot calculations'!BI19 | AE30: ='Slot calculations'!BJ19 | AF30: ='Slot calculations'!BK19 | ... AJ30: ='Slot calculations'!BO19
A31: 16 | B31: FD/PV | E31: 0 | F31: 0 | G31: 0 | H31: 0 | I31: 0 | J31: 0 | K31: =REPT(CHAR(152),SUM($V31:$X31)+Y31+AE31) | L31: =REPT(CHAR(152),SUM($V31:$X31)+Z31+AF31) | M31: =REPT(CHAR(152),SUM($V31:$X31)+AA31+AG31) | N31: =REPT(CHAR(152),SUM($V31:$X31)+AB31+AH31) | O31: =REPT(CHAR(152),SUM($V31:$X31)+AC31+AI31) | P31: =REPT(CHAR(152),SUM($V31:$X31)+AD31+AJ31) | Q31: =(Q82+Q83)/2 | R31: =(R82+R83)/2 | S31: =(S82+S83)/2 | T31: {=MEDIAN(IF($A$14:$A$77=$A31,Q$14:Q$77))} | U31: {=MEDIAN(IF($A$14:$A$77=$A31,R$14:R$77))} | V31: =IF(Q31>T31,1,0) | W31: =IF(R31>U31,1,0) | X31: =IF(OR(AND(A31<9,S31>3),AND(A31>8,S31<4)),1,0) | Y31: ='Slot calculations'!BD20 | Z31: ='Slot calculations'!BE20 | AA31: ='Slot calculations'!BF20 | AB31: ='Slot calculations'!BG20 | AC31: ='Slot calculations'!BH20 | AD31: ='Slot calculations'!BI20 | AE31: ='Slot calculations'!BJ20 | AF31: ='Slot calculations'!BK20 | ... AJ31: ='Slot calculations'!BO20
A32: 8 | B32: Syracuse | E32: 1 | F32: 0 | G32: 0 | H32: 0 | I32: 0 | J32: 0 | K32: =REPT(CHAR(152),SUM($V32:$X32)+Y32+AE32) | L32: =REPT(CHAR(152),SUM($V32:$X32)+Z32+AF32) | M32: =REPT(CHAR(152),SUM($V32:$X32)+AA32+AG32) | N32: =REPT(CHAR(152),SUM($V32:$X32)+AB32+AH32) | O32: =REPT(CHAR(152),SUM($V32:$X32)+AC32+AI32) | P32: =REPT(CHAR(152),SUM($V32:$X32)+AD32+AJ32) | Q32: =VLOOKUP(B32,Quality!A$2:B$252,2,FALSE) | R32: =VLOOKUP(B32,Size!A$2:B$299,2,FALSE) | S32: =VLOOKUP(B32,Mom!A$2:B$68,2,FALSE) | T32: {=MEDIAN(IF($A$14:$A$77=$A32,Q$14:Q$77))} | U32: {=MEDIAN(IF($A$14:$A$77=$A32,R$14:R$77))} | V32: =IF(Q32>T32,1,0) | W32: =IF(R32>U32,1,0) | X32: =IF(OR(AND(A32<9,S32>3),AND(A32>8,S32<4)),1,0) | Y32: ='Slot calculations'!BD21 | Z32: ='Slot calculations'!BE21 | AA32: ='Slot calculations'!BF21 | AB32: ='Slot calculations'!BG21 | AC32: ='Slot calculations'!BH21 | AD32: ='Slot calculations'!BI21 | AE32: ='Slot calculations'!BJ21 | AF32: ='Slot calculations'!BK21 | ... AJ32: ='Slot calculations'!BO21
A33: 9 | B33: Baylor | E33: 0 | F33: 0 | G33: 0 | H33: 0 | I33: 0 | J33: 0 | K33: =REPT(CHAR(152),SUM($V33:$X33)+Y33+AE33) | L33: =REPT(CHAR(152),SUM($V33:$X33)+Z33+AF33) | M33: =REPT(CHAR(152),SUM($V33:$X33)+AA33+AG33) | N33: =REPT(CHAR(152),SUM($V33:$X33)+AB33+AH33) | O33: =REPT(CHAR(152),SUM($V33:$X33)+AC33+AI33) | P33: =REPT(CHAR(152),SUM($V33:$X33)+AD33+AJ33) | Q33: =VLOOKUP(B33,Quality!A$2:B$252,2,FALSE) | R33: =VLOOKUP(B33,Size!A$2:B$299,2,FALSE) | S33: =VLOOKUP(B33,Mom!A$2:B$68,2,FALSE) | T33: {=MEDIAN(IF($A$14:$A$77=$A33,Q$14:Q$77))} | U33: {=MEDIAN(IF($A$14:$A$77=$A33,R$14:R$77))} | V33: =IF(Q33>T33,1,0) | W33: =IF(R33>U33,1,0) | X33: =IF(OR(AND(A33<9,S33>3),AND(A33>8,S33<4)),1,0) | Y33: ='Slot calculations'!BD22 | Z33: ='Slot calculations'!BE22 | AA33: ='Slot calculations'!BF22 | AB33: ='Slot calculations'!BG22 | AC33: ='Slot calculations'!BH22 | AD33: ='Slot calculations'!BI22 | AE33: ='Slot calculations'!BJ22 | AF33: ='Slot calculations'!BK22 | ... AJ33: ='Slot calculations'!BO22
A34: 5 | B34: Marquette | E34: 1 | F34: 1 | G34: 0 | H34: 0 | I34: 0 | J34: 0 | K34: =REPT(CHAR(152),SUM($V34:$X34)+Y34+AE34) | L34: =REPT(CHAR(152),SUM($V34:$X34)+Z34+AF34) | M34: =REPT(CHAR(152),SUM($V34:$X34)+AA34+AG34) | N34: =REPT(CHAR(152),SUM($V34:$X34)+AB34+AH34) | O34: =REPT(CHAR(152),SUM($V34:$X34)+AC34+AI34) | P34: =REPT(CHAR(152),SUM($V34:$X34)+AD34+AJ34) | Q34: =VLOOKUP(B34,Quality!A$2:B$252,2,FALSE) | R34: =VLOOKUP(B34,Size!A$2:B$299,2,FALSE) | S34: =VLOOKUP(B34,Mom!A$2:B$68,2,FALSE) | T34: {=MEDIAN(IF($A$14:$A$77=$A34,Q$14:Q$77))} | U34: {=MEDIAN(IF($A$14:$A$77=$A34,R$14:R$77))} | V34: =IF(Q34>T34,1,0) | W34: =IF(R34>U34,1,0) | X34: =IF(OR(AND(A34<9,S34>3),AND(A34>8,S34<4)),1,0) | Y34: ='Slot calculations'!BD23 | Z34: ='Slot calculations'!BE23 | AA34: ='Slot calculations'!BF23 | AB34: ='Slot calculations'!BG23 | AC34: ='Slot calculations'!BH23 | AD34: ='Slot calculations'!BI23 | AE34: ='Slot calculations'!BJ23 | AF34: ='Slot calculations'!BK23 | ... AJ34: ='Slot calculations'!BO23
A35: 12 | B35: Murray State | E35: 0 | F35: 0 | G35: 0 | H35: 0 | I35: 0 | J35: 0 | K35: =REPT(CHAR(152),SUM($V35:$X35)+Y35+AE35) | L35: =REPT(CHAR(152),SUM($V35:$X35)+Z35+AF35) | M35: =REPT(CHAR(152),SUM($V35:$X35)+AA35+AG35) | N35: =REPT(CHAR(152),SUM($V35:$X35)+AB35+AH35) | O35: =REPT(CHAR(152),SUM($V35:$X35)+AC35+AI35) | P35: =REPT(CHAR(152),SUM($V35:$X35)+AD35+AJ35) | Q35: =VLOOKUP(B35,Quality!A$2:B$252,2,FALSE) | R35: =VLOOKUP(B35,Size!A$2:B$299,2,FALSE) | S35: =VLOOKUP(B35,Mom!A$2:B$68,2,FALSE) | T35: {=MEDIAN(IF($A$14:$A$77=$A35,Q$14:Q$77))} | U35: {=MEDIAN(IF($A$14:$A$77=$A35,R$14:R$77))} | V35: =IF(Q35>T35,1,0) | W35: =IF(R35>U35,1,0) | X35: =IF(OR(AND(A35<9,S35>3),AND(A35>8,S35<4)),1,0) | Y35: ='Slot calculations'!BD24 | Z35: ='Slot calculations'!BE24 | AA35: ='Slot calculations'!BF24 | AB35: ='Slot calculations'!BG24 | AC35: ='Slot calculations'!BH24 | AD35: ='Slot calculations'!BI24 | AE35: ='Slot calculations'!BJ24 | AF35: ='Slot calculations'!BK24 | ... AJ35: ='Slot calculations'!BO24
A36: 4 | B36: Florida State | E36: 1 | F36: 0 | G36: 0 | H36: 0 | I36: 0 | J36: 0 | K36: =REPT(CHAR(152),SUM($V36:$X36)+Y36+AE36) | L36: =REPT(CHAR(152),SUM($V36:$X36)+Z36+AF36) | M36: =REPT(CHAR(152),SUM($V36:$X36)+AA36+AG36) | N36: =REPT(CHAR(152),SUM($V36:$X36)+AB36+AH36) | O36: =REPT(CHAR(152),SUM($V36:$X36)+AC36+AI36) | P36: =REPT(CHAR(152),SUM($V36:$X36)+AD36+AJ36) | Q36: =VLOOKUP(B36,Quality!A$2:B$252,2,FALSE) | R36: =VLOOKUP(B36,Size!A$2:B$299,2,FALSE) | S36: =VLOOKUP(B36,Mom!A$2:B$68,2,FALSE) | T36: {=MEDIAN(IF($A$14:$A$77=$A36,Q$14:Q$77))} | U36: {=MEDIAN(IF($A$14:$A$77=$A36,R$14:R$77))} | V36: =IF(Q36>T36,1,0) | W36: =IF(R36>U36,1,0) | X36: =IF(OR(AND(A36<9,S36>3),AND(A36>8,S36<4)),1,0) | Y36: ='Slot calculations'!BD25 | Z36: ='Slot calculations'!BE25 | AA36: ='Slot calculations'!BF25 | AB36: ='Slot calculations'!BG25 | AC36: ='Slot calculations'!BH25 | AD36: ='Slot calculations'!BI25 | AE36: ='Slot calculations'!BJ25 | AF36: ='Slot calculations'!BK25 | ... AJ36: ='Slot calculations'!BO25
A37: 13 | B37: Vermont | E37: 0 | F37: 0 | G37: 0 | H37: 0 | I37: 0 | J37: 0 | K37: =REPT(CHAR(152),SUM($V37:$X37)+Y37+AE37) | L37: =REPT(CHAR(152),SUM($V37:$X37)+Z37+AF37) | M37: =REPT(CHAR(152),SUM($V37:$X37)+AA37+AG37) | N37: =REPT(CHAR(152),SUM($V37:$X37)+AB37+AH37) | O37: =REPT(CHAR(152),SUM($V37:$X37)+AC37+AI37) | P37: =REPT(CHAR(152),SUM($V37:$X37)+AD37+AJ37) | Q37: =VLOOKUP(B37,Quality!A$2:B$252,2,FALSE) | R37: =VLOOKUP(B37,Size!A$2:B$299,2,FALSE) | S37: =VLOOKUP(B37,Mom!A$2:B$68,2,FALSE) | T37: {=MEDIAN(IF($A$14:$A$77=$A37,Q$14:Q$77))} | U37: {=MEDIAN(IF($A$14:$A$77=$A37,R$14:R$77))} | V37: =IF(Q37>T37,1,0) | W37: =IF(R37>U37,1,0) | X37: =IF(OR(AND(A37<9,S37>3),AND(A37>8,S37<4)),1,0) | Y37: ='Slot calculations'!BD26 | Z37: ='Slot calculations'!BE26 | AA37: ='Slot calculations'!BF26 | AB37: ='Slot calculations'!BG26 | AC37: ='Slot calculations'!BH26 | AD37: ='Slot calculations'!BI26 | AE37: ='Slot calculations'!BJ26 | AF37: ='Slot calculations'!BK26 | ... AJ37: ='Slot calculations'!BO26
A38: 6 | B38: Buffalo | E38: 1 | F38: 1 | G38: 1 | H38: 0 | I38: 0 | J38: 0 | K38: =REPT(CHAR(152),SUM($V38:$X38)+Y38+AE38) | L38: =REPT(CHAR(152),SUM($V38:$X38)+Z38+AF38) | M38: =REPT(CHAR(152),SUM($V38:$X38)+AA38+AG38) | N38: =REPT(CHAR(152),SUM($V38:$X38)+AB38+AH38) | O38: =REPT(CHAR(152),SUM($V38:$X38)+AC38+AI38) | P38: =REPT(CHAR(152),SUM($V38:$X38)+AD38+AJ38) | Q38: =VLOOKUP(B38,Quality!A$2:B$252,2,FALSE) | R38: =VLOOKUP(B38,Size!A$2:B$299,2,FALSE) | S38: =VLOOKUP(B38,Mom!A$2:B$68,2,FALSE) | T38: {=MEDIAN(IF($A$14:$A$77=$A38,Q$14:Q$77))} | U38: {=MEDIAN(IF($A$14:$A$77=$A38,R$14:R$77))} | V38: =IF(Q38>T38,1,0) | W38: =IF(R38>U38,1,0) | X38: =IF(OR(AND(A38<9,S38>3),AND(A38>8,S38<4)),1,0) | Y38: ='Slot calculations'!BD27 | Z38: ='Slot calculations'!BE27 | AA38: ='Slot calculations'!BF27 | AB38: ='Slot calculations'!BG27 | AC38: ='Slot calculations'!BH27 | AD38: ='Slot calculations'!BI27 | AE38: ='Slot calculations'!BJ27 | AF38: ='Slot calculations'!BK27 | ... AJ38: ='Slot calculations'!BO27
A39: 11 | B39: AS/SJ | E39: 0 | F39: 0 | G39: 0 | H39: 0 | I39: 0 | J39: 0 | K39: =REPT(CHAR(152),SUM($V39:$X39)+Y39+AE39) | L39: =REPT(CHAR(152),SUM($V39:$X39)+Z39+AF39) | M39: =REPT(CHAR(152),SUM($V39:$X39)+AA39+AG39) | N39: =REPT(CHAR(152),SUM($V39:$X39)+AB39+AH39) | O39: =REPT(CHAR(152),SUM($V39:$X39)+AC39+AI39) | P39: =REPT(CHAR(152),SUM($V39:$X39)+AD39+AJ39) | Q39: =(Q84+Q85)/2 | R39: =(R84+R85)/2 | S39: =(S84+S85)/2 | T39: {=MEDIAN(IF($A$14:$A$77=$A39,Q$14:Q$77))} | U39: {=MEDIAN(IF($A$14:$A$77=$A39,R$14:R$77))} | V39: =IF(Q39>T39,1,0) | W39: =IF(R39>U39,1,0) | X39: =IF(OR(AND(A39<9,S39>3),AND(A39>8,S39<4)),1,0) | Y39: ='Slot calculations'!BD28 | Z39: ='Slot calculations'!BE28 | AA39: ='Slot calculations'!BF28 | AB39: ='Slot calculations'!BG28 | AC39: ='Slot calculations'!BH28 | AD39: ='Slot calculations'!BI28 | AE39: ='Slot calculations'!BJ28 | AF39: ='Slot calculations'!BK28 | ... AJ39: ='Slot calculations'!BO28
A40: 3 | B40: Texas Tech | E40: 1 | F40: 0 | G40: 0 | H40: 0 | I40: 0 | J40: 0 | K40: =REPT(CHAR(152),SUM($V40:$X40)+Y40+AE40) | L40: =REPT(CHAR(152),SUM($V40:$X40)+Z40+AF40) | M40: =REPT(CHAR(152),SUM($V40:$X40)+AA40+AG40) | N40: =REPT(CHAR(152),SUM($V40:$X40)+AB40+AH40) | O40: =REPT(CHAR(152),SUM($V40:$X40)+AC40+AI40) | P40: =REPT(CHAR(152),SUM($V40:$X40)+AD40+AJ40) | Q40: =VLOOKUP(B40,Quality!A$2:B$252,2,FALSE) | R40: =VLOOKUP(B40,Size!A$2:B$299,2,FALSE) | S40: =VLOOKUP(B40,Mom!A$2:B$68,2,FALSE) | T40: {=MEDIAN(IF($A$14:$A$77=$A40,Q$14:Q$77))} | U40: {=MEDIAN(IF($A$14:$A$77=$A40,R$14:R$77))} | V40: =IF(Q40>T40,1,0) | W40: =IF(R40>U40,1,0) | X40: =IF(OR(AND(A40<9,S40>3),AND(A40>8,S40<4)),1,0) | Y40: ='Slot calculations'!BD29 | Z40: ='Slot calculations'!BE29 | AA40: ='Slot calculations'!BF29 | AB40: ='Slot calculations'!BG29 | AC40: ='Slot calculations'!BH29 | AD40: ='Slot calculations'!BI29 | AE40: ='Slot calculations'!BJ29 | AF40: ='Slot calculations'!BK29 | ... AJ40: ='Slot calculations'!BO29
...

Sheet Size
A1: Team | B1: Prior NCAA tournament success
A2: Air Force | B2: 0.11269994
A3: Akron | B3: 0.67240521
A4: Alabama | B4: 5.831166
A5: Alabama St | B5: 0.066498463
A6: Albany | B6: 1.4038988
A7: Alcorn St | B7: 0.014411519
A8: American | B8: 0.65119191
A9: Appalachian St | B9: 0.018014399
A10: Arizona | B10: 45.954457
A11: Arizona State | B11: 1.1559094
A12: Arkansas | B12: 8.4020949
A13: Arkansas Little Rock | B13: 2.5666508
... A299: Yale | B299: 2.56

Sheet Mom
A1: Team | B1: Wins in last five regular season games
A2: Abilene Christian | B2: 5
A3: Arizona State | B3: 3
A4: Auburn | B4: 5
A5: Baylor | B5: 1
A6: Belmont | B6: 4
A7: Bradley | B7: 4
A8: Buffalo | B8: 5
A9: Cincinnati | B9: 3
A10: Colgate | B10: 5
A11: Duke | B11: 4
A12: Fairleigh Dickinson | B12: 5
A13: Florida | B13: 2
... A76: Arizona State | B76: 3

Sheet Quality
A1: TEAM | B1: BPI
A2: Abilene Christian | B2: 1.7
A3: Akron | B3: 3.1
A4: Alabama | B4: 7.2
A5: American | B5: -1.2
A6: Appalachian State | B6: -1.8
A7: Arizona | B7: 4.6
A8: Arizona State | B8: 7.4
A9: Arkansas | B9: 7
A10: Army | B10: -3.2
A11: Auburn | B11: 15
A12: Austin Peay | B12: 4
A13: Ball State | B13: 2.9
... A252: Yale | B252: 6.1

Sheet Brackets - prob
A1: Team | B1: R64 | C1: R32 | D1: S16 | E1: E8 | F1: F4 | G1: C6
A2: Duke | B2: 0.99 | C2: 0.9 | D2: 0.72 | E2: 0.53 | F2: 0.32 | G2: 0.184
A3: N Dakota St./NC Central | B3: 0.01 | C3: 0.01 | D3: 0.003 | E3: 0.0002 | F3: 0.00066666667 | G3: 0.0001
A4: VCU | B4: 0.53 | C4: 0.05 | D4: 0.02 | E4: 0.008 | F4: 0.002 | G4: 0.0001
A5: UCF | B5: 0.47 | C5: 0.04 | D5: 0.01 | E5: 0.004 | F5: 0.001 | G5: 0.0001
A6: Mississippi State | B6: 0.82 | C6: 0.38 | D6: 0.08 | E6: 0.03 | F6: 0.01 | G6: 0.005
A7: Liberty | B7: 0.18 | C7: 0.04 | D7: 0.004 | E7: 0.0002 | F7: 0.00066666667 | G7: 0.0001
A8: Virginia Tech | B8: 0.87 | C8: 0.55 | D8: 0.16 | E8: 0.09 | F8: 0.04 | G8: 0.02
A9: Saint Louis | B9: 0.13 | C9: 0.03 | D9: 0.003 | E9: 0.0002 | F9: 0.00066666667 | G9: 0.0001
A10: Maryland | B10: 0.64 | C10: 0.32 | D10: 0.13 | E10: 0.04 | F10: 0.01 | G10: 0.004
A11: Belmont/Temple | B11: 0.36 | C11: 0.14 | D11: 0.015 | E11: 0.003 | F11: 0.001 | G11: 0.0001
A12: LSU | B12: 0.85 | C12: 0.5 | D12: 0.16 | E12: 0.04 | F12: 0.01 | G12: 0.005
A13: Yale | B13: 0.15 | C13: 0.04 | D13: 0.006 | E13: 0.0002 | F13: 0.00066666667 | G13: 0.0001
... A65: Abilene Christian | B65: 0.03 | C65: 0.004 | D65: 0.001 | E65: 0.0046666667 | F65: 0.00066666667 | G65: 0.0001

Sheet Brackets - freq
A1: Team | B1: R64 | C1: R32 | D1: S16 | E1: E8 | F1: F4 | G1: C6
A2: Duke | B2: 0.976 | C2: 0.945 | D2: 0.88 | E2: 0.731 | F2: 0.592 | G2: 0.424
A3: N Dakota St./NC Central | B3: 0.024 | C3: 0.012 | D3: 0.008 | E3: 0.006 | F3: 0.003 | G3: 0.001
A4: VCU | B4: 0.467 | C4: 0.02 | D4: 0.009 | E4: 0.004 | F4: 0.002 | G4: 0.001
A5: UCF | B5: 0.533 | C5: 0.023 | D5: 0.01 | E5: 0.004 | F5: 0.002 | G5: 0.001
A6: Mississippi State | B6: 0.751 | C6: 0.24 | D6: 0.019 | E6: 0.007 | F6: 0.003 | G6: 0.001
A7: Liberty | B7: 0.249 | C7: 0.053 | D7: 0.007 | E7: 0.003 | F7: 0.001 | G7: 0.001
A8: Virginia Tech | B8: 0.874 | C8: 0.659 | D8: 0.06 | E8: 0.024 | F8: 0.009 | G8: 0.004
A9: Saint Louis | B9: 0.126 | C9: 0.049 | D9: 0.007 | E9: 0.003 | F9: 0.001 | G9: 0.001
A10: Maryland | B10: 0.769 | C10: 0.249 | D10: 0.05 | E10: 0.009 | F10: 0.004 | G10: 0.002
A11: Belmont/Temple | B11: 0.231 | C11: 0.064 | D11: 0.009 | E11: 0.003 | F11: 0.001 | G11: 0.001
A12: LSU | B12: 0.854 | C12: 0.633 | D12: 0.198 | E12: 0.036 | F12: 0.017 | G12: 0.007
A13: Yale | B13: 0.146 | C13: 0.054 | D13: 0.01 | E13: 0.004 | F13: 0.002 | G13: 0.001
... A65: Abilene Christian | B65: 0.037 | C65: 0.018 | D65: 0.011 | E65: 0.003 | F65: 0.002 | G65: 0.001

Sheet Slot calculations
A1: Team | B1: S | H1: p0 | N1: p0f0 | T1: Expected point difference | Z1: Ratio | AF1: Variance | AL1: Variance difference | AR1: Ratio | AX1: Value ratio | BD1: Value | BJ1: BAB
B2: R64 | C2: R32 | D2: S16 | E2: E8 | F2: F4 | G2: C2 | H2: R64 | I2: R32 | J2: S16 | K2: E8 | L2: F4 | M2: C2 | N2: R64 | O2: R32 | P2: S16 | Q2: E8 | R2: F4 | S2: C2 | T2: R64 | U2: R32 | V2: S16 | W2: E8 | X2: F4 | Y2: C2 | Z2: R64 | AA2: R32 | AB2: S16 | AC2: E8 | AD2: F4 | AE2: C2 | AF2: R64 | AG2: R32 | AH2: S16 | AI2: E8 | AJ2: F4 | AK2: C2 | AL2: R64 | AM2: R32 | AN2: S16 | AO2: E8 | AP2: F4 | AQ2: C2 | AR2: R64 | AS2: R32 | AT2: S16 | AU2: E8 | AV2: F4 | AW2: C2 | AX2: R64 | AY2: R32 | AZ2: S16 | BA2: E8 | BB2: F4 | BC2: C2 | BD2: R64 | BE2: R32 | BF2: S16 | BG2: E8 | BH2: F4 | BI2: C2 | BJ2: R64 | BK2: R32 | BL2: S16 | BM2: E8 | BN2: F4 | BO2: C2
A3: Duke | B3: =SUMPRODUCT('Brackets - prob'!B2:B3,'Brackets - freq'!B2:B3) | C3: =SUMPRODUCT('Brackets - prob'!C2:C5,'Brackets - freq'!C2:C5) | D3: =SUMPRODUCT('Brackets - prob'!D2:D9,'Brackets - freq'!D2:D9) | E3: =SUMPRODUCT('Brackets - prob'!E2:E17,'Brackets - freq'!E2:E17) | F3: =SUMPRODUCT('Brackets - prob'!F2:F33,'Brackets - freq'!F2:F33) | G3: =SUMPRODUCT('Brackets - prob'!G2:G65,'Brackets - freq'!G2:G65) | H3: =MAX('Brackets - prob'!B2:B3) | I3: =MAX('Brackets - prob'!C2:C5) | J3: =MAX('Brackets - prob'!D2:D9) | K3: =MAX('Brackets - prob'!E2:E17) | L3: =MAX('Brackets - prob'!F2:F33) | M3: =MAX('Brackets - prob'!G2:G65) | N3: =AVERAGEIF('Brackets - prob'!B2:B3,"="&H3,'Brackets - freq'!B2:B3)*H3 | O3: =AVERAGEIF('Brackets - prob'!C2:C5,"="&I3,'Brackets - freq'!C2:C5)*I3 | P3: =AVERAGEIF('Brackets - prob'!D2:D9,"="&J3,'Brackets - freq'!D2:D9)*J3 | Q3: =AVERAGEIF('Brackets - prob'!E2:E17,"="&K3,'Brackets - freq'!E2:E17)*K3 | R3: =AVERAGEIF('Brackets - prob'!F2:F33,"="&L3,'Brackets - freq'!F2:F33)*L3 | S3: =AVERAGEIF('Brackets - prob'!G2:G65,"="&M3,'Brackets - freq'!G2:G65)*M3 | T3: =Bracket!E$2*('Brackets - prob'!B2-H3) | U3: =Bracket!F$2*('Brackets - prob'!C2-I3) | V3: =Bracket!G$2*('Brackets - prob'!D2-J3) | W3: =Bracket!H$2*('Brackets - prob'!E2-K3) | X3: =Bracket!I$2*('Brackets - prob'!F2-L3) | Y3: =Bracket!J$2*('Brackets - prob'!G2-M3) | Z3: =SUM(T3:$T3) | AA3: =SUM($T3:U3) | AB3: =SUM($T3:V3) | AC3: =SUM($T3:W3) | AD3: =SUM($T3:X3) | AE3: =SUM($T3:Y3) | AF3: ='Brackets - prob'!B2*(1-'Brackets - prob'!B2-2*'Brackets - freq'!B2+2*B3)+B3-B3^2 | AG3: ='Brackets - prob'!C2*(1-'Brackets - prob'!C2-2*'Brackets - freq'!C2+2*C3)+C3-C3^2 | AH3: ='Brackets - prob'!D2*(1-'Brackets - prob'!D2-2*'Brackets - freq'!D2+2*D3)+D3-D3^2 | AI3: ='Brackets - prob'!E2*(1-'Brackets - prob'!E2-2*'Brackets - freq'!E2+2*E3)+E3-E3^2 | AJ3: ='Brackets - prob'!F2*(1-'Brackets - prob'!F2-2*'Brackets - freq'!F2+2*F3)+F3-F3^2 | AK3: ='Brackets - prob'!G2*(1-'Brackets - prob'!G2-2*'Brackets - freq'!G2+2*G3)+G3-G3^2 | AL3: =Bracket!E$2^2*(('Brackets - prob'!B2-H3)*(1+2*B3)-'Brackets - prob'!B2^2+H3^2-2*('Brackets - prob'!B2*'Brackets - freq'!B2-N3)) | AM3: =Bracket!F$2^2*(('Brackets - prob'!C2-I3)*(1+2*C3)-'Brackets - prob'!C2^2+I3^2-2*('Brackets - prob'!C2*'Brackets - freq'!C2-O3)) | AN3: =Bracket!G$2^2*(('Brackets - prob'!D2-J3)*(1+2*D3)-'Brackets - prob'!D2^2+J3^2-2*('Brackets - prob'!D2*'Brackets - freq'!D2-P3)) | AO3: =Bracket!H$2^2*(('Brackets - prob'!E2-K3)*(1+2*E3)-'Brackets - prob'!E2^2+K3^2-2*('Brackets - prob'!E2*'Brackets - freq'!E2-Q3)) | AP3: =Bracket!I$2^2*(('Brackets - prob'!F2-L3)*(1+2*F3)-'Brackets - prob'!F2^2+L3^2-2*('Brackets - prob'!F2*'Brackets - freq'!F2-R3)) | AQ3: =Bracket!J$2^2*(('Brackets - prob'!G2-M3)*(1+2*G3)-'Brackets - prob'!G2^2+M3^2-2*('Brackets - prob'!G2*'Brackets - freq'!G2-S3)) | AR3: =SUM($AL3:AL3) | AS3: =SUM($AL3:AM3) | AT3: =SUM($AL3:AN3) | AU3: =SUM($AL3:AO3) | AV3: =SUM($AL3:AP3) | AW3: =SUM($AL3:AQ3) | AX3: =IF(Z3=0,0,AR3/Z3) | AY3: =IF(AA3=0,0,AS3/AA3) | AZ3: =IF(AB3=0,0,AT3/AB3) | BA3: =IF(AC3=0,0,AU3/AC3) | BB3: =IF(AD3=0,0,AV3/AD3) | BC3: =IF(AE3=0,0,AW3/AE3) | BD3: =IF(OR(AX3=0,AX3<=-1),1,0) | BE3: =IF(OR(AY3=0,AY3<=-1),1,0) | BF3: =IF(OR(AZ3=0,AZ3<=-1),1,0) | BG3: =IF(OR(BA3=0,BA3<=-1),1,0) | BH3: =IF(OR(BB3=0,BB3<=-1),1,0) | BI3: =IF(OR(BC3=0,BC3<=-1),1,0) | BJ3: =IF(AND('Brackets - prob'!B2>H3-0.5,'Brackets - freq'!B2/'Brackets - prob'!B2<N3/H3^2),1,0) | BK3: =IF(AND('Brackets - prob'!C2>I3-0.5,'Brackets - freq'!C2/'Brackets - prob'!C2<O3/I3^2),1,0) | BL3: =IF(AND('Brackets - prob'!D2>J3-0.5,'Brackets - freq'!D2/'Brackets - prob'!D2<P3/J3^2),1,0) | BM3: =IF(AND('Brackets - prob'!E2>K3-0.5,'Brackets - freq'!E2/'Brackets - prob'!E2<Q3/K3^2),1,0) | BN3: =IF(AND('Brackets - prob'!F2>L3-0.5,'Brackets - freq'!F2/'Brackets - prob'!F2<R3/L3^2),1,0) | BO3: =IF(AND('Brackets - prob'!G2>M3-0.5,'Brackets - freq'!G2/'Brackets - prob'!G2<S3/M3^2),1,0)
A4: NDS/NCC | B4: =B3 | C4: =C3 | D4: =D3 | E4: =E3 | F4: =F3 | G4: =G3 | H4: =H3 | I4: =I3 | ... S4: =S3 | T4: =Bracket!E$2*('Brackets - prob'!B3-H4) | U4: =Bracket!F$2*('Brackets - prob'!C3-I4) | V4: =Bracket!G$2*('Brackets - prob'!D3-J4) | W4: =Bracket!H$2*('Brackets - prob'!E3-K4) | X4: =Bracket!I$2*('Brackets - prob'!F3-L4) | Y4: =Bracket!J$2*('Brackets - prob'!G3-M4) | Z4: =SUM(T4:$T4) | AA4: =SUM($T4:U4) | AB4: =SUM($T4:V4) | AC4: =SUM($T4:W4) | AD4: =SUM($T4:X4) | AE4: =SUM($T4:Y4) | AF4: ='Brackets - prob'!B3*(1-'Brackets - prob'!B3-2*'Brackets - freq'!B3+2*B4)+B4-B4^2 | AG4: ='Brackets - prob'!C3*(1-'Brackets - prob'!C3-2*'Brackets - freq'!C3+2*C4)+C4-C4^2 | AH4: ='Brackets - prob'!D3*(1-'Brackets - prob'!D3-2*'Brackets - freq'!D3+2*D4)+D4-D4^2 | AI4: ='Brackets - prob'!E3*(1-'Brackets - prob'!E3-2*'Brackets - freq'!E3+2*E4)+E4-E4^2 | AJ4: ='Brackets - prob'!F3*(1-'Brackets - prob'!F3-2*'Brackets - freq'!F3+2*F4)+F4-F4^2 | AK4: ='Brackets - prob'!G3*(1-'Brackets - prob'!G3-2*'Brackets - freq'!G3+2*G4)+G4-G4^2 | AL4: =Bracket!E$2^2*(('Brackets - prob'!B3-H4)*(1+2*B4)-'Brackets - prob'!B3^2+H4^2-2*('Brackets - prob'!B3*'Brackets - freq'!B3-N4)) | AM4: =Bracket!F$2^2*(('Brackets - prob'!C3-I4)*(1+2*C4)-'Brackets - prob'!C3^2+I4^2-2*('Brackets - prob'!C3*'Brackets - freq'!C3-O4)) | AN4: =Bracket!G$2^2*(('Brackets - prob'!D3-J4)*(1+2*D4)-'Brackets - prob'!D3^2+J4^2-2*('Brackets - prob'!D3*'Brackets - freq'!D3-P4)) | AO4: =Bracket!H$2^2*(('Brackets - prob'!E3-K4)*(1+2*E4)-'Brackets - prob'!E3^2+K4^2-2*('Brackets - prob'!E3*'Brackets - freq'!E3-Q4)) | AP4: =Bracket!I$2^2*(('Brackets - prob'!F3-L4)*(1+2*F4)-'Brackets - prob'!F3^2+L4^2-2*('Brackets - prob'!F3*'Brackets - freq'!F3-R4)) | AQ4: =Bracket!J$2^2*(('Brackets - prob'!G3-M4)*(1+2*G4)-'Brackets - prob'!G3^2+M4^2-2*('Brackets - prob'!G3*'Brackets - freq'!G3-S4)) | AR4: =SUM($AL4:AL4) | AS4: =SUM($AL4:AM4) | AT4: =SUM($AL4:AN4) | AU4: =SUM($AL4:AO4) | AV4: =SUM($AL4:AP4) | AW4: =SUM($AL4:AQ4) | AX4: =IF(Z4=0,0,AR4/Z4) | AY4: =IF(AA4=0,0,AS4/AA4) | AZ4: =IF(AB4=0,0,AT4/AB4) | BA4: =IF(AC4=0,0,AU4/AC4) | BB4: =IF(AD4=0,0,AV4/AD4) | BC4: =IF(AE4=0,0,AW4/AE4) | BD4: =IF(OR(AX4=0,AX4<=-1),1,0) | BE4: =IF(OR(AY4=0,AY4<=-1),1,0) | BF4: =IF(OR(AZ4=0,AZ4<=-1),1,0) | BG4: =IF(OR(BA4=0,BA4<=-1),1,0) | BH4: =IF(OR(BB4=0,BB4<=-1),1,0) | BI4: =IF(OR(BC4=0,BC4<=-1),1,0) | BJ4: =IF(AND('Brackets - prob'!B3>H4-0.5,'Brackets - freq'!B3/'Brackets - prob'!B3<N4/H4^2),1,0) | BK4: =IF(AND('Brackets - prob'!C3>I4-0.5,'Brackets - freq'!C3/'Brackets - prob'!C3<O4/I4^2),1,0) | BL4: =IF(AND('Brackets - prob'!D3>J4-0.5,'Brackets - freq'!D3/'Brackets - prob'!D3<P4/J4^2),1,0) | BM4: =IF(AND('Brackets - prob'!E3>K4-0.5,'Brackets - freq'!E3/'Brackets - prob'!E3<Q4/K4^2),1,0) | BN4: =IF(AND('Brackets - prob'!F3>L4-0.5,'Brackets - freq'!F3/'Brackets - prob'!F3<R4/L4^2),1,0) | BO4: =IF(AND('Brackets - prob'!G3>M4-0.5,'Brackets - freq'!G3/'Brackets - prob'!G3<S4/M4^2),1,0)
A5: VCU | B5: =SUMPRODUCT('Brackets - prob'!B4:B5,'Brackets - freq'!B4:B5) | C5: =C4 | D5: =D4 | E5: =E4 | F5: =F4 | G5: =G4 | H5: =MAX('Brackets - prob'!B4:B5) | I5: =I4 | J5: =J4 | K5: =K4 | L5: =L4 | M5: =M4 | N5: =AVERAGEIF('Brackets - prob'!B4:B5,"="&H5,'Brackets - freq'!B4:B5)*H5 | O5: =O4 | P5: =P4 | Q5: =Q4 | R5: =R4 | S5: =S4 | T5: =Bracket!E$2*('Brackets - prob'!B4-H5) | U5: =Bracket!F$2*('Brackets - prob'!C4-I5) | V5: =Bracket!G$2*('Brackets - prob'!D4-J5) | W5: =Bracket!H$2*('Brackets - prob'!E4-K5) | X5: =Bracket!I$2*('Brackets - prob'!F4-L5) | Y5: =Bracket!J$2*('Brackets - prob'!G4-M5) | Z5: =SUM(T5:$T5) | AA5: =SUM($T5:U5) | AB5: =SUM($T5:V5) | AC5: =SUM($T5:W5) | AD5: =SUM($T5:X5) | AE5: =SUM($T5:Y5) | AF5: ='Brackets - prob'!B4*(1-'Brackets - prob'!B4-2*'Brackets - freq'!B4+2*B5)+B5-B5^2 | AG5: ='Brackets - prob'!C4*(1-'Brackets - prob'!C4-2*'Brackets - freq'!C4+2*C5)+C5-C5^2 | AH5: ='Brackets - prob'!D4*(1-'Brackets - prob'!D4-2*'Brackets - freq'!D4+2*D5)+D5-D5^2 | AI5: ='Brackets - prob'!E4*(1-'Brackets - prob'!E4-2*'Brackets - freq'!E4+2*E5)+E5-E5^2 | AJ5: ='Brackets - prob'!F4*(1-'Brackets - prob'!F4-2*'Brackets - freq'!F4+2*F5)+F5-F5^2 | AK5: ='Brackets - prob'!G4*(1-'Brackets - prob'!G4-2*'Brackets - freq'!G4+2*G5)+G5-G5^2 | AL5: =Bracket!E$2^2*(('Brackets - prob'!B4-H5)*(1+2*B5)-'Brackets - prob'!B4^2+H5^2-2*('Brackets - prob'!B4*'Brackets - freq'!B4-N5)) | AM5: =Bracket!F$2^2*(('Brackets - prob'!C4-I5)*(1+2*C5)-'Brackets - prob'!C4^2+I5^2-2*('Brackets - prob'!C4*'Brackets - freq'!C4-O5)) | AN5: =Bracket!G$2^2*(('Brackets - prob'!D4-J5)*(1+2*D5)-'Brackets - prob'!D4^2+J5^2-2*('Brackets - prob'!D4*'Brackets - freq'!D4-P5)) | AO5: =Bracket!H$2^2*(('Brackets - prob'!E4-K5)*(1+2*E5)-'Brackets - prob'!E4^2+K5^2-2*('Brackets - prob'!E4*'Brackets - freq'!E4-Q5)) | AP5: =Bracket!I$2^2*(('Brackets - prob'!F4-L5)*(1+2*F5)-'Brackets - prob'!F4^2+L5^2-2*('Brackets - prob'!F4*'Brackets - freq'!F4-R5)) | AQ5: =Bracket!J$2^2*(('Brackets - prob'!G4-M5)*(1+2*G5)-'Brackets - prob'!G4^2+M5^2-2*('Brackets - prob'!G4*'Brackets - freq'!G4-S5)) | AR5: =SUM($AL5:AL5) | AS5: =SUM($AL5:AM5) | AT5: =SUM($AL5:AN5) | AU5: =SUM($AL5:AO5) | AV5: =SUM($AL5:AP5) | AW5: =SUM($AL5:AQ5) | AX5: =IF(Z5=0,0,AR5/Z5) | AY5: =IF(AA5=0,0,AS5/AA5) | AZ5: =IF(AB5=0,0,AT5/AB5) | BA5: =IF(AC5=0,0,AU5/AC5) | BB5: =IF(AD5=0,0,AV5/AD5) | BC5: =IF(AE5=0,0,AW5/AE5) | BD5: =IF(OR(AX5=0,AX5<=-1),1,0) | BE5: =IF(OR(AY5=0,AY5<=-1),1,0) | BF5: =IF(OR(AZ5=0,AZ5<=-1),1,0) | BG5: =IF(OR(BA5=0,BA5<=-1),1,0) | BH5: =IF(OR(BB5=0,BB5<=-1),1,0) | BI5: =IF(OR(BC5=0,BC5<=-1),1,0) | BJ5: =IF(AND('Brackets - prob'!B4>H5-0.5,'Brackets - freq'!B4/'Brackets - prob'!B4<N5/H5^2),1,0) | BK5: =IF(AND('Brackets - prob'!C4>I5-0.5,'Brackets - freq'!C4/'Brackets - prob'!C4<O5/I5^2),1,0) | BL5: =IF(AND('Brackets - prob'!D4>J5-0.5,'Brackets - freq'!D4/'Brackets - prob'!D4<P5/J5^2),1,0) | BM5: =IF(AND('Brackets - prob'!E4>K5-0.5,'Brackets - freq'!E4/'Brackets - prob'!E4<Q5/K5^2),1,0) | BN5: =IF(AND('Brackets - prob'!F4>L5-0.5,'Brackets - freq'!F4/'Brackets - prob'!F4<R5/L5^2),1,0) | BO5: =IF(AND('Brackets - prob'!G4>M5-0.5,'Brackets - freq'!G4/'Brackets - prob'!G4<S5/M5^2),1,0)
A6: UCF | B6: =B5 | C6: =C5 | D6: =D5 | E6: =E5 | F6: =F5 | G6: =G5 | H6: =H5 | I6: =I5 | ... S6: =S5 | T6: =Bracket!E$2*('Brackets - prob'!B5-H6) | U6: =Bracket!F$2*('Brackets - prob'!C5-I6) | V6: =Bracket!G$2*('Brackets - prob'!D5-J6) | W6: =Bracket!H$2*('Brackets - prob'!E5-K6) | X6: =Bracket!I$2*('Brackets - prob'!F5-L6) | Y6: =Bracket!J$2*('Brackets - prob'!G5-M6) | Z6: =SUM(T6:$T6) | AA6: =SUM($T6:U6) | AB6: =SUM($T6:V6) | AC6: =SUM($T6:W6) | AD6: =SUM($T6:X6) | AE6: =SUM($T6:Y6) | AF6: ='Brackets - prob'!B5*(1-'Brackets - prob'!B5-2*'Brackets - freq'!B5+2*B6)+B6-B6^2 | AG6: ='Brackets - prob'!C5*(1-'Brackets - prob'!C5-2*'Brackets - freq'!C5+2*C6)+C6-C6^2 | AH6: ='Brackets - prob'!D5*(1-'Brackets - prob'!D5-2*'Brackets - freq'!D5+2*D6)+D6-D6^2 | AI6: ='Brackets - prob'!E5*(1-'Brackets - prob'!E5-2*'Brackets - freq'!E5+2*E6)+E6-E6^2 | AJ6: ='Brackets - prob'!F5*(1-'Brackets - prob'!F5-2*'Brackets - freq'!F5+2*F6)+F6-F6^2 | AK6: ='Brackets - prob'!G5*(1-'Brackets - prob'!G5-2*'Brackets - freq'!G5+2*G6)+G6-G6^2 | AL6: =Bracket!E$2^2*(('Brackets - prob'!B5-H6)*(1+2*B6)-'Brackets - prob'!B5^2+H6^2-2*('Brackets - prob'!B5*'Brackets - freq'!B5-N6)) | AM6: =Bracket!F$2^2*(('Brackets - prob'!C5-I6)*(1+2*C6)-'Brackets - prob'!C5^2+I6^2-2*('Brackets - prob'!C5*'Brackets - freq'!C5-O6)) | AN6: =Bracket!G$2^2*(('Brackets - prob'!D5-J6)*(1+2*D6)-'Brackets - prob'!D5^2+J6^2-2*('Brackets - prob'!D5*'Brackets - freq'!D5-P6)) | AO6: =Bracket!H$2^2*(('Brackets - prob'!E5-K6)*(1+2*E6)-'Brackets - prob'!E5^2+K6^2-2*('Brackets - prob'!E5*'Brackets - freq'!E5-Q6)) | AP6: =Bracket!I$2^2*(('Brackets - prob'!F5-L6)*(1+2*F6)-'Brackets - prob'!F5^2+L6^2-2*('Brackets - prob'!F5*'Brackets - freq'!F5-R6)) | AQ6: =Bracket!J$2^2*(('Brackets - prob'!G5-M6)*(1+2*G6)-'Brackets - prob'!G5^2+M6^2-2*('Brackets - prob'!G5*'Brackets - freq'!G5-S6)) | AR6: =SUM($AL6:AL6) | AS6: =SUM($AL6:AM6) | AT6: =SUM($AL6:AN6) | AU6: =SUM($AL6:AO6) | AV6: =SUM($AL6:AP6) | AW6: =SUM($AL6:AQ6) | AX6: =IF(Z6=0,0,AR6/Z6) | AY6: =IF(AA6=0,0,AS6/AA6) | AZ6: =IF(AB6=0,0,AT6/AB6) | BA6: =IF(AC6=0,0,AU6/AC6) | BB6: =IF(AD6=0,0,AV6/AD6) | BC6: =IF(AE6=0,0,AW6/AE6) | BD6: =IF(OR(AX6=0,AX6<=-1),1,0) | BE6: =IF(OR(AY6=0,AY6<=-1),1,0) | BF6: =IF(OR(AZ6=0,AZ6<=-1),1,0) | BG6: =IF(OR(BA6=0,BA6<=-1),1,0) | BH6: =IF(OR(BB6=0,BB6<=-1),1,0) | BI6: =IF(OR(BC6=0,BC6<=-1),1,0) | BJ6: =IF(AND('Brackets - prob'!B5>H6-0.5,'Brackets - freq'!B5/'Brackets - prob'!B5<N6/H6^2),1,0) | BK6: =IF(AND('Brackets - prob'!C5>I6-0.5,'Brackets - freq'!C5/'Brackets - prob'!C5<O6/I6^2),1,0) | BL6: =IF(AND('Brackets - prob'!D5>J6-0.5,'Brackets - freq'!D5/'Brackets - prob'!D5<P6/J6^2),1,0) | BM6: =IF(AND('Brackets - prob'!E5>K6-0.5,'Brackets - freq'!E5/'Brackets - prob'!E5<Q6/K6^2),1,0) | BN6: =IF(AND('Brackets - prob'!F5>L6-0.5,'Brackets - freq'!F5/'Brackets - prob'!F5<R6/L6^2),1,0) | BO6: =IF(AND('Brackets - prob'!G5>M6-0.5,'Brackets - freq'!G5/'Brackets - prob'!G5<S6/M6^2),1,0)
A7: Mississippi State | B7: =SUMPRODUCT('Brackets - prob'!B6:B7,'Brackets - freq'!B6:B7) | C7: =SUMPRODUCT('Brackets - prob'!C6:C9,'Brackets - freq'!C6:C9) | D7: =D6 | E7: =E6 | F7: =F6 | G7: =G6 | H7: =MAX('Brackets - prob'!B6:B7) | I7: =MAX('Brackets - prob'!C6:C9) | J7: =J6 | K7: =K6 | L7: =L6 | M7: =M6 | N7: =AVERAGEIF('Brackets - prob'!B6:B7,"="&H7,'Brackets - freq'!B6:B7)*H7 | O7: =AVERAGEIF('Brackets - prob'!C6:C9,"="&I7,'Brackets - freq'!C6:C9)*I7 | P7: =P6 | Q7: =Q6 | R7: =R6 | S7: =S6 | T7: =Bracket!E$2*('Brackets - prob'!B6-H7) | U7: =Bracket!F$2*('Brackets - prob'!C6-I7) | V7: =Bracket!G$2*('Brackets - prob'!D6-J7) | W7: =Bracket!H$2*('Brackets - prob'!E6-K7) | X7: =Bracket!I$2*('Brackets - prob'!F6-L7) | Y7: =Bracket!J$2*('Brackets - prob'!G6-M7) | Z7: =SUM(T7:$T7) | AA7: =SUM($T7:U7) | AB7: =SUM($T7:V7) | AC7: =SUM($T7:W7) | AD7: =SUM($T7:X7) | AE7: =SUM($T7:Y7) | AF7: ='Brackets - prob'!B6*(1-'Brackets - prob'!B6-2*'Brackets - freq'!B6+2*B7)+B7-B7^2 | AG7: ='Brackets - prob'!C6*(1-'Brackets - prob'!C6-2*'Brackets - freq'!C6+2*C7)+C7-C7^2 | AH7: ='Brackets - prob'!D6*(1-'Brackets - prob'!D6-2*'Brackets - freq'!D6+2*D7)+D7-D7^2 | AI7: ='Brackets - prob'!E6*(1-'Brackets - prob'!E6-2*'Brackets - freq'!E6+2*E7)+E7-E7^2 | AJ7: ='Brackets - prob'!F6*(1-'Brackets - prob'!F6-2*'Brackets - freq'!F6+2*F7)+F7-F7^2 | AK7: ='Brackets - prob'!G6*(1-'Brackets - prob'!G6-2*'Brackets - freq'!G6+2*G7)+G7-G7^2 | AL7: =Bracket!E$2^2*(('Brackets - prob'!B6-H7)*(1+2*B7)-'Brackets - prob'!B6^2+H7^2-2*('Brackets - prob'!B6*'Brackets - freq'!B6-N7)) | AM7: =Bracket!F$2^2*(('Brackets - prob'!C6-I7)*(1+2*C7)-'Brackets - prob'!C6^2+I7^2-2*('Brackets - prob'!C6*'Brackets - freq'!C6-O7)) | AN7: =Bracket!G$2^2*(('Brackets - prob'!D6-J7)*(1+2*D7)-'Brackets - prob'!D6^2+J7^2-2*('Brackets - prob'!D6*'Brackets - freq'!D6-P7)) | AO7: =Bracket!H$2^2*(('Brackets - prob'!E6-K7)*(1+2*E7)-'Brackets - prob'!E6^2+K7^2-2*('Brackets - prob'!E6*'Brackets - freq'!E6-Q7)) | AP7: =Bracket!I$2^2*(('Brackets - prob'!F6-L7)*(1+2*F7)-'Brackets - prob'!F6^2+L7^2-2*('Brackets - prob'!F6*'Brackets - freq'!F6-R7)) | AQ7: =Bracket!J$2^2*(('Brackets - prob'!G6-M7)*(1+2*G7)-'Brackets - prob'!G6^2+M7^2-2*('Brackets - prob'!G6*'Brackets - freq'!G6-S7)) | AR7: =SUM($AL7:AL7) | AS7: =SUM($AL7:AM7) | AT7: =SUM($AL7:AN7) | AU7: =SUM($AL7:AO7) | AV7: =SUM($AL7:AP7) | AW7: =SUM($AL7:AQ7) | AX7: =IF(Z7=0,0,AR7/Z7) | AY7: =IF(AA7=0,0,AS7/AA7) | AZ7: =IF(AB7=0,0,AT7/AB7) | BA7: =IF(AC7=0,0,AU7/AC7) | BB7: =IF(AD7=0,0,AV7/AD7) | BC7: =IF(AE7=0,0,AW7/AE7) | BD7: =IF(OR(AX7=0,AX7<=-1),1,0) | BE7: =IF(OR(AY7=0,AY7<=-1),1,0) | BF7: =IF(OR(AZ7=0,AZ7<=-1),1,0) | BG7: =IF(OR(BA7=0,BA7<=-1),1,0) | BH7: =IF(OR(BB7=0,BB7<=-1),1,0) | BI7: =IF(OR(BC7=0,BC7<=-1),1,0) | BJ7: =IF(AND('Brackets - prob'!B6>H7-0.5,'Brackets - freq'!B6/'Brackets - prob'!B6<N7/H7^2),1,0) | BK7: =IF(AND('Brackets - prob'!C6>I7-0.5,'Brackets - freq'!C6/'Brackets - prob'!C6<O7/I7^2),1,0) | BL7: =IF(AND('Brackets - prob'!D6>J7-0.5,'Brackets - freq'!D6/'Brackets - prob'!D6<P7/J7^2),1,0) | BM7: =IF(AND('Brackets - prob'!E6>K7-0.5,'Brackets - freq'!E6/'Brackets - prob'!E6<Q7/K7^2),1,0) | BN7: =IF(AND('Brackets - prob'!F6>L7-0.5,'Brackets - freq'!F6/'Brackets - prob'!F6<R7/L7^2),1,0) | BO7: =IF(AND('Brackets - prob'!G6>M7-0.5,'Brackets - freq'!G6/'Brackets - prob'!G6<S7/M7^2),1,0)
A8: Liberty | B8: =B7 | C8: =C7 | D8: =D7 | E8: =E7 | F8: =F7 | G8: =G7 | H8: =H7 | I8: =I7 | ... S8: =S7 | T8: =Bracket!E$2*('Brackets - prob'!B7-H8) | U8: =Bracket!F$2*('Brackets - prob'!C7-I8) | V8: =Bracket!G$2*('Brackets - prob'!D7-J8) | W8: =Bracket!H$2*('Brackets - prob'!E7-K8) | X8: =Bracket!I$2*('Brackets - prob'!F7-L8) | Y8: =Bracket!J$2*('Brackets - prob'!G7-M8) | Z8: =SUM(T8:$T8) | AA8: =SUM($T8:U8) | AB8: =SUM($T8:V8) | AC8: =SUM($T8:W8) | AD8: =SUM($T8:X8) | AE8: =SUM($T8:Y8) | AF8: ='Brackets - prob'!B7*(1-'Brackets - prob'!B7-2*'Brackets - freq'!B7+2*B8)+B8-B8^2 | AG8: ='Brackets - prob'!C7*(1-'Brackets - prob'!C7-2*'Brackets - freq'!C7+2*C8)+C8-C8^2 | AH8: ='Brackets - prob'!D7*(1-'Brackets - prob'!D7-2*'Brackets - freq'!D7+2*D8)+D8-D8^2 | AI8: ='Brackets - prob'!E7*(1-'Brackets - prob'!E7-2*'Brackets - freq'!E7+2*E8)+E8-E8^2 | AJ8: ='Brackets - prob'!F7*(1-'Brackets - prob'!F7-2*'Brackets - freq'!F7+2*F8)+F8-F8^2 | AK8: ='Brackets - prob'!G7*(1-'Brackets - prob'!G7-2*'Brackets - freq'!G7+2*G8)+G8-G8^2 | AL8: =Bracket!E$2^2*(('Brackets - prob'!B7-H8)*(1+2*B8)-'Brackets - prob'!B7^2+H8^2-2*('Brackets - prob'!B7*'Brackets - freq'!B7-N8)) | AM8: =Bracket!F$2^2*(('Brackets - prob'!C7-I8)*(1+2*C8)-'Brackets - prob'!C7^2+I8^2-2*('Brackets - prob'!C7*'Brackets - freq'!C7-O8)) | AN8: =Bracket!G$2^2*(('Brackets - prob'!D7-J8)*(1+2*D8)-'Brackets - prob'!D7^2+J8^2-2*('Brackets - prob'!D7*'Brackets - freq'!D7-P8)) | AO8: =Bracket!H$2^2*(('Brackets - prob'!E7-K8)*(1+2*E8)-'Brackets - prob'!E7^2+K8^2-2*('Brackets - prob'!E7*'Brackets - freq'!E7-Q8)) | AP8: =Bracket!I$2^2*(('Brackets - prob'!F7-L8)*(1+2*F8)-'Brackets - prob'!F7^2+L8^2-2*('Brackets - prob'!F7*'Brackets - freq'!F7-R8)) | AQ8: =Bracket!J$2^2*(('Brackets - prob'!G7-M8)*(1+2*G8)-'Brackets - prob'!G7^2+M8^2-2*('Brackets - prob'!G7*'Brackets - freq'!G7-S8)) | AR8: =SUM($AL8:AL8) | AS8: =SUM($AL8:AM8) | AT8: =SUM($AL8:AN8) | AU8: =SUM($AL8:AO8) | AV8: =SUM($AL8:AP8) | AW8: =SUM($AL8:AQ8) | AX8: =IF(Z8=0,0,AR8/Z8) | AY8: =IF(AA8=0,0,AS8/AA8) | AZ8: =IF(AB8=0,0,AT8/AB8) | BA8: =IF(AC8=0,0,AU8/AC8) | BB8: =IF(AD8=0,0,AV8/AD8) | BC8: =IF(AE8=0,0,AW8/AE8) | BD8: =IF(OR(AX8=0,AX8<=-1),1,0) | BE8: =IF(OR(AY8=0,AY8<=-1),1,0) | BF8: =IF(OR(AZ8=0,AZ8<=-1),1,0) | BG8: =IF(OR(BA8=0,BA8<=-1),1,0) | BH8: =IF(OR(BB8=0,BB8<=-1),1,0) | BI8: =IF(OR(BC8=0,BC8<=-1),1,0) | BJ8: =IF(AND('Brackets - prob'!B7>H8-0.5,'Brackets - freq'!B7/'Brackets - prob'!B7<N8/H8^2),1,0) | BK8: =IF(AND('Brackets - prob'!C7>I8-0.5,'Brackets - freq'!C7/'Brackets - prob'!C7<O8/I8^2),1,0) | BL8: =IF(AND('Brackets - prob'!D7>J8-0.5,'Brackets - freq'!D7/'Brackets - prob'!D7<P8/J8^2),1,0) | BM8: =IF(AND('Brackets - prob'!E7>K8-0.5,'Brackets - freq'!E7/'Brackets - prob'!E7<Q8/K8^2),1,0) | BN8: =IF(AND('Brackets - prob'!F7>L8-0.5,'Brackets - freq'!F7/'Brackets - prob'!F7<R8/L8^2),1,0) | BO8: =IF(AND('Brackets - prob'!G7>M8-0.5,'Brackets - freq'!G7/'Brackets - prob'!G7<S8/M8^2),1,0)
